# Promise - 承诺

异步：操作之间 没啥关系，同时进行多个操作
同步：同时只能做一件事

异步：代码更复杂
同步：代码简洁

promise --清楚异步操作 \*用同步一样的方式 来书写异步代码

有了 promise 之后的异步

Promise.all([
$.ajax({
url: './data/arr.txt',
dataType: 'json'
}),
$.ajax({
url: './data/json.txt',
dataType: 'json'
})
]).then(function (results) {
alert('全部都成功了');
let [arr, json] = results;
console.log(arr, json);
}, function () {
alert('至少有一个失败了')
})

promise.all 全部
promise.race 竞速 不常用

## Promise 的 then 的第二个参数和 catch 的区别

首页我们先要区分几个概念：
第一，reject 是用来抛出异常的，catch 是用来处理异常的；
第二：reject 是 Promise 的方法，而 then 和 catch 是 Promise 实例的方法（Promise.prototype.then 和 Promise.prototype.catch）。

`catch只是一个语法糖而己 还是通过then 来处理的，`

```JavaScript
Promise.prototype.catch = function(fn){
    return this.then(null,fn);
}
```

`then 的第二个参数和 catch 捕获错误信息的时候会就近原则，如果是 promise 内部报错，reject 抛出错误后，then 的第二个参数和 catch 方法都存在的情况下，只有 then 的第二个参数能捕获到，如果 then 的第二个参数不存在，则 catch 方法会捕获到。`

```JavaScript
const promise = new Promise((resolve, rejected) => {
    throw new Error('test');
});

//此时只有then的第二个参数可以捕获到错误信息
promise.then(res => {
    //
}, err => {
    console.log(err);
}).catch(err1 => {
    console.log(err1);
});


//此时catch方法可以捕获到错误信息
promise.then(res => {
    //
}).catch(err1 => {
    console.log(err1);
});


//此时只有then的第二个参数可以捕获到Promise内部抛出的错误信息
promise.then(res => {
    throw new Error('hello');
}, err => {
    console.log(err);
}).catch(err1 => {
    console.log(err1);
});

//此时只有then的第二个参数可以捕获到Promise内部抛出的错误信息
promise.then(res => {
    throw new Error('hello');
}, err => {
    console.log(err);
});


//此时catch可以捕获到Promise内部抛出的错误信息
promise.then(res => {
    throw new Error('hello');
}).catch(err1 => {
    console.log(err1);
});
```

## 两个捕获方法的比较

```JavaScript
// bad
promise
  .then(function(data) {
    // success
  }, function(err) {
    // error
  });

// good
promise
  .then(function(data) { //cb
    // success
  })
  .catch(function(err) {
    // error
  });
```

`上面代码中，第二种写法要好于第一种写法，理由是第二种写法可以捕获前面then方法执行中的错误，也更接近同步的写法（try/catch）。因此，建议总是使用catch方法，而不使用then方法的第二个参数。`
